Workbook

Sheet Summary
A1: F&B price-source coverage - global sweep
A2: Built 2026-08-06 from 18 probe agents across all six regions (eap, eca, ssa, sar, menaap, lac). Denominator throughout: 279 deep COICOP F&B leaves (269 in division 01, 10 in division 02).
A4: The sweep
A5: Candidates in your list | B5: =COUNTA(All_Candidates_685!A2:A686) | C5: rows in price_scraping_global_sources_fnb.csv
A6: Probed and viable | B6: =COUNTIF(All_Candidates_685!G2:G686,"PROBED - VIABLE") | C6: list rows that verified (list has duplicate domains, so this exceeds distinct sources)
A7: Probed and rejected | B7: =COUNTIF(All_Candidates_685!G2:G686,"PROBED - SKIP") | C7: network trace on file showing they are not usable
A8: Not probed | B8: =COUNTIF(All_Candidates_685!G2:G686,"NOT PROBED*") | C8: duplicate domain, already onboarded, or time-boxed out
A9: Total viable sources found | B9: =COUNTA(All_Viable_340!A2:A341) | C9: includes net-new finds that were NOT in your list - see Discovered_NetNew
A11: Build plan
A12: Ready now (low effort) | B12: =COUNTA(Build_Plan_215!A2:A216) | C12: endpoint verified, real sample product captured
A13: Wave 1 - WFP/CKAN fetcher extension | B13: =COUNTIF(Build_Plan_215!G2:G216,"Wave 1") | C13: ONE line each in an existing _PANELS dict. Cheapest work in the plan. Date-check each panel - stale ones exist.
A14: Wave 2 - off-the-shelf platforms | B14: =COUNTIF(Build_Plan_215!G2:G216,"Wave 2") | C14: VTEX / Shopify / WooCommerce / Magento / PrestaShop / OpenCart / NCR Freshop -> 7 generic spiders cover all of them
A15: Wave 3 - bespoke | B15: =COUNTIF(Build_Plan_215!G2:G216,"Wave 3") | C15: one custom spider or fetcher each - this is the real cost
A16: Needs more work | B16: =COUNTA(Remaining_125!A2:A126)
A17: Wave 4 - endpoint known, harder parse | B17: =COUNTIF(Remaining_125!E2:E126,"TIER_1A")+COUNTIF(Remaining_125!E2:E126,"TIER_1B") | C17: pagination, auth or awkward parsing
A18: Wave 5 - needs a discovery pass | B18: =COUNTIF(Remaining_125!E2:E126,"TIER_2") | C18: Playwright to FIND the JSON endpoint, then scrape it over plain HTTP
A20: Of the ready set: spiders to write | B20: =COUNTIF(Build_Plan_215!H2:H216,"spider")
A21: Of the ready set: fetchers to write | B21: =COUNTIF(Build_Plan_215!H2:H216,"fetcher")
A22: Distinct build units | B22: =COUNTIF(Build_Plan_215!J2:J216,"Z_bespoke")+8 | C22: bespoke sources + 7 generic platform spiders + 1 fetcher edit. Far below the raw source count.
A24: Where we lack COUNTRY coverage
A25: Countries assessed | B25: =COUNTA(Country_Coverage!B2:B161)
A26: at 50% or more of the 279 leaves | B26: =COUNTIF(Country_Coverage!E2:E161,">=50")
A27: at 30-50% | B27: =COUNTIFS(Country_Coverage!E2:E161,">=30",Country_Coverage!E2:E161,"<50")
A28: under 30% - THE GAP LIST | B28: =COUNTIF(Country_Coverage!E2:E161,"<30") | C28: itemised on Country_Gaps
A29: at zero | B29: =COUNTIF(Country_Coverage!E2:E161,0) | C29: all six Gulf states are here - one WAF, six countries
A31: Where we lack LEAF coverage (division 01)
A32: Leaves already covered | B32: =COUNTIF(Leaf_Gaps_Div01!D2:D270,"ok")
A33: Absent from EAP retail - NEW SOURCES FIX THESE | B33: =COUNTIF(Leaf_Gaps_Div01!D2:D270,"out_of_region") | C33: teff, sorghum/millet flour, camel meat and milk, cowpeas, pigeon peas, bambara beans, cocoa beans, olives, yautia, quinoa - the direct payoff of this sweep
A34: Flagged sourcing_gap | B34: =COUNTIF(Leaf_Gaps_Div01!D2:D270,"sourcing_gap") | C34: TREAT AS HYPOTHESIS - most past ones turned out to be gold gaps, not source gaps
A35: Quantity / unit-value problem | B35: =COUNTIF(Leaf_Gaps_Div01!D2:D270,"trusted_tier") | C35: no new source fixes these
A36: Unreachable by design | B36: =COUNTIF(Leaf_Gaps_Div01!D2:D270,"catch_all")+COUNTIF(Leaf_Gaps_Div01!D2:D270,"out_of_scope")
A38: Read this before trusting the numbers
A39: Leaf counts per country are ESTIMATES, not leaf lists. | C39: Agents estimated HOW MANY of the 279 leaves each source reaches, from catalog categories they actually saw. They did not enumerate WHICH leaves. There is no country-by-leaf matrix here and there cannot be one until these sources are collected and classified.
A40: Leaf_Gaps_Div01 is measured on the CURRENT corpus, which is EAP-dominant. | C40: It is the authoritative answer to "which deep leaves lack coverage" today. Division 01 only (269 of the 279).
A41: Leaf_Gaps_Div01 is a SNAPSHOT of leaf_support_table.csv taken 2026-08-06 12:28. | C41: That table is regenerated by the classifier pipeline and it MOVES. During the build of this workbook a v20 classifier run rewrote it and shifted 14 leaves into "ok" (out_of_region 21 -> 16, sourcing_gap 29 -> 19). Re-run src/prices/build/leaf_support.py and rebuild this sheet before acting on the counts.
A42: EAP rows in Country_Coverage are scope-limited. | C42: The EAP agents only looked at Pacific Islands and official/wholesale feeds. A low or zero EAP number means "no such feed found", NOT "no coverage" - EAP already has 297 manifests that were not re-measured.
A43: Your list grades poorly. | C43: Verdict is a weak prior (ACCEPT 55% viable, SUSPECT 30%, REJECT 10%). Build tier is NOISE - tier B scored 14%, worse than rows with no tier at all (55%). Do not prioritise by it. Platform labels are also unreliable - several Bolivian rows labelled VTEX/Custom are actually Shopify.
A44: A manifest existing does not mean F&B coverage exists. | C44: Six confirmed cases where an onboarded source turned out to be electronics, cosmetics, craft or pharmacy.
A45: A zero country is usually not structurally empty. | C45: Most zeros are SPA-shelled, auth-gated or WAF-blocked storefronts that a Playwright discovery pass may still crack. Treat Country_Gaps as a work queue, not a verdict.

Sheet Build_Plan_215
A1: region | B1: slug | C1: source | D1: url | E1: tier | F1: effort | G1: build_wave | H1: scaffolding | I1: build_approach | J1: bucket | K1: platform | L1: analytical_role | M1: channel | N1: currency | O1: fnb_leaves_est | P1: endpoint | Q1: evidence | R1: in_csv | S1: notes | T1: gotcha
A2: ssa | B2: ethiopia | C2: WFP Food Prices (HDX) -- Ethiopia | D2: https://data.humdata.org/dataset/wfp-food-prices-for-ethiopia | E2: TIER_1B | F2: low | G2: Wave 1 | H2: fetcher | I2: Extend _PANELS in src/prices/fetchers/_shared/eap/wfp_food_prices.py - one line per country, no new code. DATE-CHECK each panel first. | J2: A_wfp_ckan | K2: WFP/HDX CKAN | L2: official_avg | M2: official_avg | N2: ETB | O2: 45 | P2: https://data.humdata.org/api/3/action/package_show?id=wfp-food-prices-for-ethiopia | Q2: CKAN resolved -> wfp_food_prices_eth.csv, 62,131 rows. 96 distinct commodities -- richest WFP panel in this shard: full cereal set (wheat/barley/maize/sorghum/teff, each in 2-5 sub-varieties), legumes (beans x6 varieties, chickpeas, lentils, peas x3), dairy (milk, camel milk, butter x2), live animals (bull/camel/cattle/donkey/goat/ox/sheep), produce (avocado/banana/beetroot/cabbage/carrots/garlic/guava/kale/lettuce/mango/onions/oranges/papaya/potatoes/swiss chard/sweet potatoes/tomatoes), coffee, honey, oils, pasta, salt, sesame, sugar. | R2: FALSE | S2: By far the biggest single lever for Ethiopia's F&B coverage -- reaches teff (all 4 sub-varieties), live animals, and multiple dairy/legume forms that no retail source in this shard touches.
A3: lac | B3: guatemala | C3: WFP Food Prices - Guatemala | D3: https://data.humdata.org/dataset/wfp-food-prices-for-guatemala | E3: TIER_1B | F3: low | G3: Wave 1 | H3: fetcher | I3: Extend _PANELS in src/prices/fetchers/_shared/eap/wfp_food_prices.py - one line per country, no new code. DATE-CHECK each panel first. | J3: A_wfp_ckan | K3: CKAN/WFP HDX | L3: official_avg | M3: wholesale/retail (mixed) | N3: GTQ | O3: 45 | P3: CKAN dataset wfp-food-prices-for-guatemala, resource wfp_food_prices_gtm.csv | Q3: GET CSV https://data.humdata.org/dataset/.../wfp_food_prices_gtm.csv -> HTTP 200, 2.29MB, 16,178 rows. Max date confirmed 2026-06-15 (live/recent). Sample: 'Maize (white)' 100 Pounds, Wholesale, La Terminal market, GTQ 67.75 (2026-06-15). Also carrots, onions, tomatoes, beans, coffee, bananas. | R3: FALSE | S3: Wholesale + some retail channel, La Terminal market Guatemala City + others; complements but barely overlaps supermarket SKUs (fresh produce/grains/pulses focus).
A4: menaap | B4: syria | C4: WFP Food Prices - Syria (HDX) | D4: https://data.humdata.org/dataset/aa40b3a8-2bc4-4826-9d82-82189bc5f392 | E4: TIER_1B | F4: low | G4: Wave 1 | H4: fetcher | I4: Extend _PANELS in src/prices/fetchers/_shared/eap/wfp_food_prices.py - one line per country, no new code. DATE-CHECK each panel first. | J4: A_wfp_ckan | K4: WFP/HDX CKAN | L4: official_avg | M4: official_avg | N4: SYP | O4: 44 | P4: CKAN package_show -> S3 CSV | Q4: CKAN package_show -> 200, resolves wfp_food_prices_syr.csv, 275,972 rows - by far the largest panel in the set. 77 distinct commodities across all 8 categories: fruit (apples, bananas), veg (cabbage, carrots, cucumbers x2, eggplant, garlic, parsley, pumpkin, spinach, tomatoes fresh+paste), dairy (cheese x2, labaneh, fresh milk, yogurt), meat (beef minced, chicken legs/plucked, sheep), cereals (bulgur, maize local, wheat, 3 bread variants, 2 pasta variants, rice), pulses (3 bean types, lentils, 2 pea types, chickpeas), oils/fats (oil, ghee), plus sugar/salt/tea/yeast/peanut. | R4: FALSE | S4: Syria's WFP panel is the deepest of the entire shard because of dedicated crisis-monitoring granularity (parallel-market fuel/bread variants tracked separately). One-line _PANELS addition: 'syr': ('Syria', 'wfp-food-prices-for-syrian-arab-republic').
A5: ssa | B5: rwanda | C5: WFP Rwanda (HDX) | D5: https://data.humdata.org/dataset/a4a84c1c-81d1-491b-9fbe-1955ae736508 | E5: TIER_1B | F5: low | G5: Wave 1 | H5: fetcher | I5: Extend _PANELS in src/prices/fetchers/_shared/eap/wfp_food_prices.py - one line per country, no new code. DATE-CHECK each panel first. | J5: A_wfp_ckan | K5: Custom (CKAN/HDX) | L5: official_avg | M5: official_avg | N5: RWF | O5: 42 | P5: https://data.humdata.org/api/3/action/package_show?id=wfp-food-prices-for-rwanda | Q5: CKAN-resolved CSV wfp_food_prices_rwa.csv (200, 19.9MB, richest+largest panel in this shard). 151,961 rows, 65 distinct commodities, max date 2026-06-15. Extremely granular: apples, avocados, guava, mangoes, passion fruit, papaya, oranges, cauliflower, greenhouse cucumbers, zucchini, soybeans, sorghum flour, 4+ rice-origin variants, 5 livestock species (live), 4 meat species. | R5: FALSE | S5: Best WFP panel discovered across the whole shard by both commodity count and row count -- essentially a near-retail-resolution market-price census. With every retail candidate in this shard unconfirmed, this feed alone is Rwanda's current F&B backbone.
A6: lac | B6: el_salvador | C6: WFP Food Prices - El Salvador | D6: https://data.humdata.org/dataset/wfp-food-prices-for-el-salvador | E6: TIER_1B | F6: low | G6: Wave 1 | H6: fetcher | I6: Extend _PANELS in src/prices/fetchers/_shared/eap/wfp_food_prices.py - one line per country, no new code. DATE-CHECK each panel first. | J6: A_wfp_ckan | K6: CKAN/WFP HDX | L6: official_avg | M6: wholesale/retail (mixed) | N6: USD | O6: 40 | P6: CKAN dataset wfp-food-prices-for-el-salvador, resource wfp_food_prices_slv.csv | Q6: GET CSV -> HTTP 200, 7,561 rows, max date confirmed 2026-06-15 (live). Sample: 'Maize (white)' 46 KG Wholesale San Salvador USD 26.49 (2026-06-15); also 'Maize (white)' Libra Retail USD 0.34. | R6: FALSE | S6: Both wholesale and retail channel rows present; national-average style market coverage.
A7: lac | B7: nicaragua | C7: WFP Food Prices - Nicaragua | D7: https://data.humdata.org/dataset/wfp-food-prices-for-nicaragua | E7: TIER_1B | F7: low | G7: Wave 1 | H7: fetcher | I7: Extend _PANELS in src/prices/fetchers/_shared/eap/wfp_food_prices.py - one line per country, no new code. DATE-CHECK each panel first. | J7: A_wfp_ckan | K7: CKAN/WFP HDX | L7: official_avg | M7: retail | N7: USD | O7: 35 | P7: CKAN dataset wfp-food-prices-for-nicaragua, resource wfp_food_prices_nic.csv | Q7: GET CSV -> HTTP 200, max date confirmed 2026-05-15 (live). Sample: 'Plantains' Pound, Retail, National Average, USD 0.44 (2026-05-15); also squashes, tomatoes. | R7: FALSE | S7: Retail national-average channel, fresh produce focus.
A8: menaap | B8: west_bank_and_gaza | C8: WFP Food Prices - State of Palestine (HDX) | D8: https://data.humdata.org/dataset/7d06b059-5831-4101-aa68-6d9123ad65b7 | E8: TIER_1B | F8: low | G8: Wave 1 | H8: fetcher | I8: Extend _PANELS in src/prices/fetchers/_shared/eap/wfp_food_prices.py - one line per country, no new code. DATE-CHECK each panel first. | J8: A_wfp_ckan | K8: WFP/HDX CKAN | L8: official_avg | M8: official_avg | N8: ILS | O8: 33 | P8: CKAN package_show -> S3 CSV | Q8: CKAN package_show?id=wfp-food-prices-for-state-of-palestine -> 200, resolves wfp_food_prices_pse.csv, 26,815 rows. 41 commodities: fruit (apples, bananas, oranges), veg (cauliflower, cucumbers, eggplant, onions, tomatoes greenhouse), dairy (goat cheese, labaneh, milk pasteurized + powder, yogurt), meat (beef, chicken, goat), 3 rice varieties, 2 oil types (maize + olive), semolina, bottled water. | R8: FALSE | S8: Repo slug is 'west_bank_and_gaza' (iso3 PSE per countries.yaml) - HDX dataset slug is 'wfp-food-prices-for-state-of-palestine'. One-line _PANELS addition: 'pse': ('State of Palestine', 'wfp-food-prices-for-state-of-palestine').
A9: ssa | B9: malawi | C9: WFP Food Prices (HDX) -- Malawi | D9: https://data.humdata.org/dataset/wfp-food-prices-for-malawi | E9: TIER_1B | F9: low | G9: Wave 1 | H9: fetcher | I9: Extend _PANELS in src/prices/fetchers/_shared/eap/wfp_food_prices.py - one line per country, no new code. DATE-CHECK each panel first. | J9: A_wfp_ckan | K9: WFP/HDX CKAN | L9: official_avg | M9: official_avg | N9: MWK | O9: 30 | P9: https://data.humdata.org/api/3/action/package_show?id=wfp-food-prices-for-malawi | Q9: CKAN resolved -> wfp_food_prices_mwi.csv, 82,819 rows. 63 distinct commodities -- notably rich in Malawi-specific leafy greens (Amaranthus, Blackjack leaves, Cowpea leaves, Mustard leaves, Pumpkin leaves, Rape leaves) and dried small fish (bonya, kapenta, matemba, usipa, utaka), plus cereals/legumes/tubers/oil/sugar. | R9: FALSE | S9: Second-richest WFP panel in the shard. The leafy-greens and dried-fish depth here is not replicated by any retailer in this pass -- structurally complementary, not overlapping.
A10: menaap | B10: jordan | C10: WFP Food Prices - Jordan (HDX) | D10: https://data.humdata.org/dataset/fba510fd-eccf-4b34-b5f6-cc531900270b | E10: TIER_1B | F10: low | G10: Wave 1 | H10: fetcher | I10: Extend _PANELS in src/prices/fetchers/_shared/eap/wfp_food_prices.py - one line per country, no new code. DATE-CHECK each panel first. | J10: A_wfp_ckan | K10: WFP/HDX CKAN | L10: official_avg | M10: official_avg | N10: JOD | O10: 29 | P10: CKAN package_show -> S3 CSV | Q10: CKAN package_show -> 200, resolves wfp_food_prices_jor.csv, 47,943 rows. 36 commodities across all 8 categories including both olive oil AND vegetable oil as separate lines, apples/bananas/oranges (fruit), cucumbers/garlic/onions/spinach/tomatoes (veg), beef/chicken/lamb (meat), two cheese types + two milk types (dairy) - the richest, most balanced panel of the whole shard. | R10: FALSE | S10: One-line _PANELS addition: 'jor': ('Jordan', 'wfp-food-prices-for-jordan').
A11: ssa | B11: kenya | C11: WFP Kenya (HDX) | D11: https://data.humdata.org/dataset/e0d3fba6-f9a2-45d7-b949-140c455197ff | E11: TIER_1B | F11: low | G11: Wave 1 | H11: fetcher | I11: Extend _PANELS in src/prices/fetchers/_shared/eap/wfp_food_prices.py - one line per country, no new code. DATE-CHECK each panel first. | J11: A_wfp_ckan | K11: Custom (CKAN/HDX, same pattern as existing src/prices/fetchers/_shared/eap/wfp_food_prices.py) | L11: official_avg | M11: official_avg | N11: KES | O11: 28 | P11: https://data.humdata.org/api/3/action/package_show?id=wfp-food-prices-for-kenya | Q11: CKAN package_show resolved CSV at wfp_food_prices_ken.csv (200, 3.6MB). 27,837 rows, 51 distinct commodities, max date 2026-07-15 (current). Retail+wholesale mixed pricetype. Sample: Maize (white) KES 1480/90kg wholesale Mombasa. | R11: FALSE | S11: Direct extension of the existing shared EAP WFP fetcher module -- just add ken to the _PANELS dict. 51 commodities incl. camel meat/milk (not covered by any retailer) is the standout addition.
A12: ssa | B12: central_african_republic | C12: WFP Central African Republic (HDX) | D12: https://data.humdata.org/dataset/e9f27b34-f511-498c-a7f8-fe8d2321f7ba | E12: TIER_1B | F12: low | G12: Wave 1 | H12: fetcher | I12: Extend _PANELS in src/prices/fetchers/_shared/eap/wfp_food_prices.py - one line per country, no new code. DATE-CHECK each panel first. | J12: A_wfp_ckan | K12: Custom (CKAN/HDX) | L12: official_avg | M12: official_avg | N12: XAF | O12: 28 | P12: https://data.humdata.org/api/3/action/package_show?id=wfp-food-prices-for-central-african-republic | Q12: CKAN-resolved CSV wfp_food_prices_caf.csv (200, 3.6MB). 30,356 rows, 39 distinct commodities (tied with Rwanda for richest panel in this shard), max date 2026-06-15. Commodities incl. Meat (antelope smoked, gazelle smoked -- bushmeat), Fish (catfish/frozen/sardine canned/smoked), Sesame, Groundnuts (shelled/unshelled), Charcoal. | R12: FALSE | S12: With no live retail candidate, this is effectively the ONLY viable F&B price source for CAR in this shard. The bushmeat commodities (antelope, gazelle) are a rare hit on the 'Other meat' leaf (01.1.2.2.9) that almost no supermarket source in the wider repo reaches.
A13: menaap | B13: iraq | C13: WFP Food Prices - Iraq (HDX) | D13: https://data.humdata.org/dataset/7d8955eb-37d2-4087-80e9-cae1aaa242f5 | E13: TIER_1B | F13: low | G13: Wave 1 | H13: fetcher | I13: Extend _PANELS in src/prices/fetchers/_shared/eap/wfp_food_prices.py - one line per country, no new code. DATE-CHECK each panel first. | J13: A_wfp_ckan | K13: WFP/HDX CKAN | L13: official_avg | M13: official_avg | N13: IQD | O13: 26 | P13: CKAN package_show -> S3 CSV | Q13: CKAN package_show -> 200, resolves wfp_food_prices_irq.csv, 56,712 rows. 49 commodities - largest non-Syria commodity list, includes dates, eggplant, cheese (local), yogurt, three rice varieties (regular/Indian/basmati), three wheat-flour sourcing variants (Turkey/local/generic). | R13: FALSE | S13: One-line _PANELS addition: 'irq': ('Iraq', 'wfp-food-prices-for-iraq').
... A118: menaap | B118: libya | C118: Al Mustawda (big.ly) | D118: https://big.ly/food | E118: TIER_1A | F118: low | G118: Wave 2 | H118: spider | I118: Generic OpenCart spider | J118: G_opencart | K118: OpenCart | L118: retailer_sku | M118: supermarket | N118: LYD | O118: 20 | P118: /food (OpenCart category route, SSR) | Q118: curl GET https://big.ly/food -> 200, 208KB HTML. OpenCart platform (theme 'renoxa'). Dedicated /food category (h2 title 'طعام'). Product cards parse cleanly: 'باذنجان' (Eggplant) 6.00 د.ل, 'بازلاء خضراء' (Green peas) 6.00 د.ل, 'بصل أحمر جاف' (Dry red onion) 3.50 د.ل. | R118: TRUE | S118: Sample was the fresh-produce subcategory only; '20,000+ completed orders' per CSV note suggests a larger catalog behind /food's 'subcategories' menu than what I paginated. Re-probe to enumerate all food subcategories before scaffolding.
A119: sar | B119: sri_lanka | C119: Carkeells | D119: https://carkeells.lk/en-gb/catalog/grocery | E119: TIER_1A | F119: low | G119: Wave 2 | H119: spider | I119: Generic OpenCart spider | J119: G_opencart | K119: OpenCart | L119: retailer_sku | M119: pharmacy | N119: LKR | O119: 15 | Q119: curl 200/21-64KB, plain OpenCart SSR HTML, `opencart` string present in body. GET /en-gb/catalog/grocery/food-products -> 200/64KB with real prices: Rs.525.00, Rs.375.00, Rs.595.00, Rs.160.00 etc (excluding a Rs.0.00 placeholder row). Confirmed as shard's own AI_NOTES suggested: a small grocery/beverages tail (2 subcategories) bolted onto a cosmetics/health/haircare-dominant OpenCart store. | R119: TRUE | S119: Real but tiny (~55 SKUs total across grocery+beverages per shard notes). Low priority -- everything it carries is already covered more deeply by Glomark/OnlineKade/SPAR2U.
A120: lac | B120: jamaica | C120: CoolMarket Groceries | D120: https://www.coolmarket.com/groceries.html | E120: TIER_1A | F120: low | G120: Wave 2 | H120: spider | I120: Generic Magento/GraphQL spider (incl. the mcprod.<domain> pattern) | J120: H_magento | K120: Magento | L120: retailer_sku | M120: supermarket | N120: JMD | O120: 170 | P120: SSR HTML Magento listing/PDP (data-price-amount attrs) | Q120: curl 200/4.04MB (Magento). data-price-amount attributes throughout: 'NESTLÉ Kit Kat 4 Bar Milk Chocolate 45g' JMD 204.00. 591 product-item-link matches on this single paginated listing page, consistent with CSV's '1,386 grocery items' claim. | R120: TRUE | S120: CSV called this the best Jamaica source; confirmed — deep grocery catalog with clean Magento price markup.
A121: menaap | B121: egypt | C121: Spinneys Egypt | D121: https://spinneys-egypt.com/ | E121: TIER_1B | F121: low | G121: Wave 2 | H121: spider | I121: Generic Magento/GraphQL spider (incl. the mcprod.<domain> pattern) | J121: H_magento | K121: Nuxt + Magento 2 (mcprod.<domain> backend pattern) | L121: retailer_sku | M121: supermarket | N121: EGP | O121: 165 | P121: https://mcprod.spinneys-egypt.com/graphql (Magento GraphQL, POST, no auth) | Q121: curl homepage -> 200, Nuxt fingerprint, config.apiURL 'https://spinneys-egypt.com/graphql' (direct proxy 400s on POST body, use mcprod subdomain instead). Direct curl POST to https://mcprod.spinneys-egypt.com/graphql (search:'rice') -> 200 clean JSON: 'El Shorouk Rice - 5 Kg' EGP 163.95, 'Dayma Rice - 1K' EGP 45.25. | R121: TRUE | S121: Upper-mid chain, third confirmed 'mcprod.<retailer-domain>/graphql' Magento site in Egypt (with Hyper One, Seoudi) -- strong signal of a shared storefront vendor to check for more Egyptian retailers on this stack. Categories incl. Fruits&Vegetables(916), Meat&Poultry(135), Seafood&Fish(137), Cheese/Dairy/Eggs(1844), Bakery&Bread(460), Frozen(998).
A122: menaap | B122: tunisia | C122: Carrefour Tunisia | D122: https://www.carrefour.tn/ | E122: TIER_1B | F122: low | G122: Wave 2 | H122: spider | I122: Generic Magento/GraphQL spider (incl. the mcprod.<domain> pattern) | J122: H_magento | K122: Magento 2 | L122: retailer_sku | M122: supermarket | N122: TND | O122: 165 | P122: /graphql (Magento GraphQL, POST, no auth) | Q122: curl homepage -> 200 but tiny 8.8KB SPA shell (data-media-backend=back.carrefour.tn). Playwright network trace found same-origin GraphQL traffic at /graphql. Direct curl POST to https://www.carrefour.tn/graphql (search:'riz') -> 200 clean JSON, NO Cloudflare/Akamai block: 'Riz Djerbien' TND 19.20, 'Riz Basmati' TND 8.49. categoryList query confirms full hypermarket taxonomy. | R122: FALSE | S122: Found via local operator search, not CSV. Distinct backend/operator from Carrefour Egypt's MAF/Akamai stack -- not WAF-hardened at all. Categories: Le marché(1082, likely fresh produce/meat/fish), Épicerie Salée(1292), Épicerie Sucrée(1654), Crèmerie et Produits Laitiers(671), Surgelés(312), Boissons(335). Strongest single Tunisia source found.
A123: menaap | B123: egypt | C123: Seoudi Market | D123: https://seoudisupermarket.com/ | E123: TIER_1B | F123: low | G123: Wave 2 | H123: spider | I123: Generic Magento/GraphQL spider (incl. the mcprod.<domain> pattern) | J123: H_magento | K123: Nuxt + Magento 2 (mcprod.<domain> backend pattern) | L123: retailer_sku | M123: supermarket | N123: EGP | O123: 160 | P123: https://mcprod.seoudisupermarket.com/graphql (Magento GraphQL, POST, no auth) | Q123: curl homepage -> 200, Magento+Nuxt fingerprint. Page source contains apiURL 'https://mcprod.seoudisupermarket.com/graphql'. Direct curl POST (search:'rice') -> 200 clean JSON: 'Al Doha Beyti Rice, Easy Rice Edition - 320g' EGP 25.75, 'Rehana Rice - 1kg' EGP 40.45. | R123: TRUE | S123: Established Cairo chain. Categories incl. Fruits&Vegetables(616), Meat/Poultry/Fishery(216), Dairy/Eggs/Cheese(1385), Cold Cuts&Deli(240), Bakery(471), Frozen(1146), Hot Drinks(1093). Same vendor pattern as Hyper One -- likely a shared Egyptian Magento/Nuxt storefront agency worth checking for other Egyptian retailers.
A124: menaap | B124: egypt | C124: Hyper One | D124: https://www.hyperone.com.eg/ | E124: TIER_1B | F124: low | G124: Wave 2 | H124: spider | I124: Generic Magento/GraphQL spider (incl. the mcprod.<domain> pattern) | J124: H_magento | K124: Nuxt + Magento 2 (mcprod.<domain> backend pattern) | L124: retailer_sku | M124: supermarket | N124: EGP | O124: 155 | P124: https://mcprod.hyperone.com.eg/graphql (Magento GraphQL, POST, no auth) | Q124: Bare domain hyperone.com.eg does not resolve; www. subdomain -> 200, Nuxt SPA. window.__NUXT__.config exposes apiUrl 'https://mcprod.hyperone.com.eg/graphql'. Direct curl POST to that endpoint (search:'rice') -> 200 clean JSON: 'Top Value Luxury Egyptian Rice - 1K' EGP 26.95, 'Meeza Egyptian Rice -1K' EGP 25.95. (The site's own www.hyperone.com.eg/graphql proxy path 400s on malformed body -- use the mcprod subdomain directly.) | R124: TRUE | S124: Large Egyptian-owned hypermarket, welfare-relevant per CSV. Categories incl. Fruits&Vegetables(172), Butchery&Poultry(59), Seafood(28), Dairy/Eggs/Cheese(521), Bakery(125), Herbs&Spices(291), Pickles(37).
A125: menaap | B125: egypt | C125: Gourmet Egypt | D125: https://gourmetegypt.com/ | E125: TIER_1B | F125: low | G125: Wave 2 | H125: spider | I125: Generic Magento/GraphQL spider (incl. the mcprod.<domain> pattern) | J125: H_magento | K125: Magento 2 | L125: retailer_sku | M125: supermarket | N125: EGP | O125: 150 | P125: /graphql (Magento GraphQL, POST, no auth) | Q125: curl homepage -> 200, Magento fingerprint. REST /rest/V1/products -> 401 (needs token, expected default). GraphQL POST /graphql (search:'rice') -> 200, clean JSON: 'Kohinoor Basmati Rice' EGP 195, 'Tilda Basmati Rice' EGP 180. categoryList query confirms full-line taxonomy. | R125: TRUE | S125: Premium/imported grocer. Categories: Meat/Poultry/Seafood(380), Bakery(317), Dairy&Eggs(637), Fruits&Vegetables(362), Frozen(568), Food Cupboard(1453), Beverages(871), Desserts(296), Chips&Snacks(469), Chocolate&Sweets(796).
A126: ssa | B126: kenya | C126: Chandarana Foodplus | D126: https://foodplus.co.ke/ | E126: TIER_1B | F126: low | G126: Wave 2 | H126: spider | I126: Generic Magento/GraphQL spider (incl. the mcprod.<domain> pattern) | J126: H_magento | K126: Magento | L126: retailer_sku | M126: supermarket | N126: KES | O126: 150 | P126: /rest/V1/products, /rest/V1/categories | Q126: The CSV's domain (chandaranafoodplus.com) is NXDOMAIN. Real domain foodplus.co.ke resolves and is Magento (not WooCommerce as CSV's platform column claims). GET /rest/V1/categories -> 200, no auth, full taxonomy incl. Fresh Fruits(146)/Fresh Vegetables(291)/Milk Butter Eggs(157)/Yoghurt(306)/Cheese(244)/Fresh Meat(102)/Deli(90), 18,205 products total. GET /rest/V1/products?searchCriteria[pageSize]=3 -> 200, 8KB JSON, sample 'C/CARE SCRUBBING BRUSH HANDLE A14' KES 165. | R126: TRUE | S126: Premium/expatriate chain per CSV; deepest single-source taxonomy verified in this shard. Domain correction is the key finding -- CSV's chandaranafoodplus.com does not resolve at all.
A127: lac | B127: panama | C127: Riba Smith | D127: https://www.ribasmith.com/ | E127: TIER_1B | F127: low | G127: Wave 2 | H127: spider | I127: Generic Magento/GraphQL spider (incl. the mcprod.<domain> pattern) | J127: H_magento | K127: Magento 2 | L127: retailer_sku | M127: supermarket | N127: USD | O127: 150 | P127: /graphql | Q127: POST /graphql {products(search:"arroz",pageSize:5){...}} -> HTTP 200 JSON. Sample: 'ARROZ PELIN ARROZ ESPECIAL 20 LBS' USD 16.48. | R127: FALSE | S127: Full-line premium PA chain; GraphQL open, no auth required for product search.
A128: lac | B128: dominican_republic | C128: Supermercados Nacional | D128: https://www.supermercadosnacional.com/ | E128: TIER_1B | F128: low | G128: Wave 2 | H128: spider | I128: Generic Magento/GraphQL spider (incl. the mcprod.<domain> pattern) | J128: H_magento | K128: Magento 2 | L128: retailer_sku | M128: supermarket | N128: DOP | O128: 150 | P128: /graphql | Q128: POST /graphql {products(search:"arroz",pageSize:5){...}} -> HTTP 200 JSON. Sample: 'Arroz Selecto Líder 10 Lb' DOP 327.95. | R128: FALSE | S128: Full-line DR chain, GraphQL open.
A129: lac | B129: curacao | C129: Van den Tweel Supermarket | D129: https://shopvdtcuracao.com/ | E129: TIER_1B | F129: low | G129: Wave 2 | H129: spider | I129: Generic Magento/GraphQL spider (incl. the mcprod.<domain> pattern) | J129: H_magento | K129: Magento 2 | L129: retailer_sku | M129: supermarket | N129: ANG | O129: 140 | P129: /graphql | Q129: POST /graphql {products(search:"melk",pageSize:5){...}} -> HTTP 200 JSON. Sample: 'AH Volle melk' ANG 3.29; also 'AH Magere melk' ANG 2.89, 'AH Halfvolle melk' ANG 2.89. | R129: FALSE | S129: Full-line CW chain (dairy confirmed), Albert Heijn-sourced private label suggests Dutch supply chain.
A130: lac | B130: british_virgin_islands | C130: RiteWay Food Markets | D130: https://www.riteway.vg/ | E130: TIER_1A | F130: low | G130: Wave 2 | H130: spider | I130: Generic Magento/GraphQL spider (incl. the mcprod.<domain> pattern) | J130: H_magento | K130: Magento 2 (custom 'Roadtown' theme) | L130: retailer_sku | M130: supermarket | N130: USD | O130: 130 | P130: /shop-groceries.html (SSR category listing) | Q130: GET /shop-groceries.html -> HTTP 200, 1.9MB SSR HTML with real Magento product-item cards. Sample product names: 'Fresh Ground Beef', 'Pork Tenderloin', 'Extra Sharp Cheddar Bar', 'Bakerly Brioche Hot Dog Buns'. Prices in same page: $4.99, $8.99, $39.99, $24.99, $7.99 (data-price-amount attrs). GraphQL endpoint (/graphql) returns HTTP 404 via the Varnish edge — GraphQL module likely disabled — but SSR category pages carry full name+price so Tier 1A applies instead. | R130: FALSE | S130: 60-year BVI chain, 9 stores, dedicated online-ordering platform ('RiteWay Online') with next-day delivery.
A131: lac | B131: jamaica | C131: Virtual Mart Jamaica | D131: https://www.virtualmartja.com/ | E131: TIER_1A | F131: low | G131: Wave 2 | H131: spider | I131: Generic Magento/GraphQL spider (incl. the mcprod.<domain> pattern) | J131: H_magento | K131: Magento | L131: retailer_sku | M131: supermarket | N131: JMD | O131: 100 | P131: SSR HTML Magento listing/PDP (data-price-amount attrs) | Q131: curl 200/225KB (Magento). data-price-amount price blocks confirmed, e.g. J$2,471.29 special-price product (id 106209). CSV notes groceries plus hardware/business-supplies categories. | R131: TRUE | S131: Mixed grocery + hardware/household catalog; F&B is a subset of a broader general-merchandise store.
... A136: eca | B136: italy | C136: Conad | D136: https://spesaonline.conad.it/ | E136: TIER_1A | F136: low | G136: Wave 3 | H136: spider | I136: One bespoke spider or fetcher per source | J136: Z_bespoke | K136: Custom (Sapo-family) | L136: retailer_sku | M136: supermarket | N136: EUR | O136: 170 | P136: /p/<slug>--<id> | Q136: GET / -> 200, 475KB, Sapo/Next hybrid. 15 unique real /p/<slug>--<id> product links on the homepage alone, spanning mozzarella, organic eggs, free-range eggs, water, chicken breast, carrots, toilet paper. EUR prices in SSR HTML (6,55 €, 2,49€, 5,24 €, 1,99€ ...). | R136: TRUE | S136: Largest Italian chain by share per CSV. Homepage alone already spans dairy, eggs, fresh meat, fresh produce, beverages, non-food -- strong full-line signal.
A137: eap | B137: malaysia | C137: KPDNHEP PriceCatcher (data.gov.my) | D137: https://storage.data.gov.my/pricecatcher/ | E137: TIER_1B | F137: low | G137: Wave 3 | H137: fetcher | I137: One bespoke spider or fetcher per source | J137: Z_bespoke | K137: Custom (static gov open-data bucket, no auth, no rate limit hit) | L137: official_avg | N137: MYR | O137: 160 | P137: /pricecatcher/pricecatcher_YYYY-MM.csv + /pricecatcher/lookup_item.csv (+ presumably lookup_premise.csv) | Q137: GET https://storage.data.gov.my/pricecatcher/pricecatcher_2026-08.csv -> 200, 8.9MB CSV, 345,029 rows (date,premise_code,item_code,price) for August 2026 alone; monthly files exist back to program start (pricecatcher_YYYY-MM.csv, also daily YYYY-MM-DD variants and a *_preview.parquet). Companion GET .../lookup_item.csv -> 200, 758-row item master (item_code,item,unit,item_group,item_category). Sample: item_code=1 'AYAM BERSIH - STANDARD' unit=1kg; premise_code=2, 2026-08-01, price=MYR 11.00. | R137: FALSE | S137: KPDNHEP's official daily price-monitoring program across 500+ registered premises nationwide (wet markets, supermarkets, minimarkets, hypermarkets), 758 SKUs total. Item-group breakdown: AYAM(10, chicken), DAGING(32, meat), BAHAN LAUT(38, fresh seafood), IKAN DARAT(4, freshwater fish), IKAN DALAM TIN(11, canned fish), HASIL LAUT KERING(4, dried seafood), SAYUR-SAYURAN(40, vegetables) + BAWANG(11, onions) + UBI KENTANG(3, potato), BUAH-BUAHAN(17, fruit), BERAS(19, rice), TEPUNG(8, flour), MEE/BIHUN/KUEY TEOW(28+3+2, noodles), MINYAK DAN LEMAK(39, oils/fats), TELUR(11, eggs), SUSU BAYI(20)+KRIMER DAN SUSU TEPUNG(23, dairy/milk powder), KACANG(7, nuts/pulses), REMPAH RATUS berbungkus+tidak(30+18, spices/condiments), KICAP DAN SOS(20, sauces), GULA(4, sugar), MINUMAN(47)+TERSEDIA MINUM(25, beverages) -- roughly 600 of the 758 items are food/beverage; the remainder (toiletries, stationery, diapers) rides the same monitoring program and is excluded downstream by the food gate. True whole-catalog walker: bulk monthly file, no pagination, no auth. Malaysia currently has zero official_avg/wholesale manifest in the repo -- this closes that gap outright and is the single strongest source found this session.
A138: eca | B138: malta | C138: PaviPama | D138: https://www.pavipama.com.mt/ | E138: TIER_1B | F138: low | G138: Wave 3 | H138: spider | I138: One bespoke spider or fetcher per source | J138: Z_bespoke | K138: Custom | L138: retailer_sku | M138: supermarket | N138: EUR | O138: 160 | P138: /api/cli/ecommerce/products/featured?p=0&store= (also /api/cli/categories) | Q138: curl 200 (after -L to /app/), Playwright network sniff found open API https://pavipama.com.mt/api/cli/ecommerce/products/featured?p=0&store= -> plain curl with Origin/Referer headers returns HTTP 200, 32.8KB JSON, 20 products/page. Sample: 'ACQUA FRIZZANTE 500ML' price 0.25 EUR, brand CONAD. /api/cli/categories returns 23 top-level categories: CONFECTIONERY, FRUIT & VEG, DELICATESSEN, FISH, BUTCHER, FROZEN, CHILLED, BABY, PERSONAL CARE, PASTA SHOP, FOODS, CELLAR, BAKERY, BEVERAGES, PETSHOP, CLEANING, HEALTH, etc. | R138: TRUE | S138: CSV URL (pavishopping.com) was DEAD (NXDOMAIN). Correct current domain found via WebSearch: pavipama.com.mt. Genuinely full-line: fruit&veg, fish, butcher, frozen, chilled, bakery, beverages, cellar, pasta shop confirmed as real top-level categories.
A139: eca | B139: armenia | C139: Parma | D139: https://parma.am/en/ | E139: TIER_1A | F139: low | G139: Wave 3 | H139: spider | I139: One bespoke spider or fetcher per source | J139: Z_bespoke | K139: Custom (Next.js) | L139: retailer_sku | M139: supermarket | N139: AMD | O139: 160 | P139: /en/product/shop?slug=<category>, /en/product/category?slug=<id> | Q139: GET /en/product/shop?slug=only-in-parma -> 200, 539KB HTML. Full category tree (baby-food, alcoholic-beverages, bakery, beef, basturma-sudjuk, battery...). Server-rendered dram prices in raw HTML: e.g. 233 է, 10387 է, 8514 է. | R139: TRUE | S139: Full grocery taxonomy incl. baby food, alcohol, bakery, fresh/cured meat (basturma). No login/geo wall hit.
A140: sar | B140: sri_lanka | C140: Glomark | D140: https://glomark.lk/ | E140: TIER_1A | F140: low | G140: Wave 3 | H140: spider | I140: One bespoke spider or fetcher per source | J140: Z_bespoke | K140: Custom PHP (ZENEDGE-fronted) | L140: retailer_sku | M140: supermarket | N140: LKR | O140: 160 | Q140: curl 200/1.14MB SSR HTML on /shop-now. 102 distinct subcategory URLs (/<path>/c/<id> and /<path>/<sub>/sc/<id>) spanning bakery(bread,buns,cake,cookies,savoury,sweet), beverages(coffee,tea,water,juices,malt,soft-drinks,sport/energy), chilled(cheese,cream,curd,desserts,pasteurized-milk,ready-to-cook,spreads,yogurt), fresh(fish: fresh-water+sea; fruits: imported+local; meat: beef,lamb,mutton,pork,poultry,ready-to-cook,value-added; vegetable: exotic,low-country,up-country), frozen(ready-to-cook,ready-to-eat,processed fish/meat/veg-fruit), grocery, household, pharmaceuticals. PDP confirmed: 'Banno Basmati Biriyani Rice 500G' Rs.250 (h1 + price both present, 767KB page). | R140: FALSE | S140: Best single find of this shard -- 'Sri Lanka's first global market', a genuine full-line supermarket (fresh meat by cut, two fish types, imported+local fruit, three vegetable tiers) served entirely over plain SSR HTML with no WAF encountered. Should be the first onboarding priority for Sri Lanka.
A141: lac | B141: bolivia | C141: Hipermaxi | D141: https://www.hipermaxi.com/ | E141: TIER_1A | F141: low | G141: Wave 3 | H141: spider | I141: One bespoke spider or fetcher per source | J141: Z_bespoke | K141: Next.js/Custom | L141: retailer_sku | M141: supermarket | N141: BOB | O141: 160 | P141: SSR HTML (no API needed) | Q141: curl 200/791KB, Next.js SSR. Prices server-rendered directly in HTML with schema-labelled blocks: 'Carne Molida de Segunda' (ground beef) Bs 40.50; 'Coca Cola Original 3 L' Bs 17.10. Full meat + beverage + grocery categories visible. | R141: TRUE | S141: Largest Bolivian supermarket chain per CSV; strongest Bolivia source, prices render server-side with no API needed.
A142: eca | B142: romania | C142: Freshful by eMAG | D142: https://www.freshful.ro/ | E142: TIER_1A | F142: low | G142: Wave 3 | H142: spider | I142: One bespoke spider or fetcher per source | J142: Z_bespoke | K142: Next.js | L142: retailer_sku | M142: supermarket | N142: RON | O142: 150 | P142: SSR HTML, no API needed | Q142: curl 200, 566KB SSR HTML (__NEXT_DATA__), real prices in raw HTML: '12,99 lei', '20,00 Lei', '56,99 Lei', '47,98 Lei', '23,03 Lei' | R142: TRUE | S142: Matches the brief's own worked example. Fresh produce with named local-producer attribution per CSV notes.
A143: eca | B143: kazakhstan | C143: Galmart | D143: https://galmart.kz/ | E143: TIER_1A | F143: low | G143: Wave 3 | H143: spider | I143: One bespoke spider or fetcher per source | J143: Z_bespoke | K143: Custom | L143: retailer_sku | M143: supermarket | N143: KZT | O143: 150 | P143: SSR HTML | Q143: curl 200, 142KB, real prices in raw HTML: '2 650₸', '2 850₸', '1 456₸', '1 835₸', '2 310₸', '2 100₸' | R143: TRUE | S143: Premium Astana chain with deep dairy taxonomy per CSV (mare/camel/goat milk as separate categories).
A144: eca | B144: slovenia | C144: Mercator Online | D144: https://mercatoronline.si/ | E144: TIER_1A | F144: low | G144: Wave 3 | H144: spider | I144: One bespoke spider or fetcher per source | J144: Z_bespoke | K144: Custom | L144: retailer_sku | M144: supermarket | N144: EUR | O144: 150 | P144: SSR HTML | Q144: curl 200, 767KB, real prices in raw HTML: '150,00 EUR', '60,00 EUR', '3,99€' | R144: TRUE | S144: 18,000+ products, delivery to 99% of Slovenian addresses per CSV; PC30 (30-day-lowest, omnibus) field noted but not verified in this pass.
A145: eca | B145: estonia | C145: Prisma Estonia | D145: https://www.prismamarket.ee/ | E145: TIER_1A | F145: low | G145: Wave 3 | H145: spider | I145: One bespoke spider or fetcher per source | J145: Z_bespoke | K145: Next.js | L145: retailer_sku | M145: supermarket | N145: EUR | O145: 150 | P145: SSR HTML / __NEXT_DATA__ JSON blob | Q145: curl 200, 367KB, Next.js SSR (__NEXT_DATA__ valid JSON with props.pageProps), real prices in raw HTML: '1,85 €', '12,33 €', '3,28 €' | R145: TRUE | S145: -
A146: eca | B146: armenia | C146: Supermarket.am | D146: https://supermarket.am/en/ | E146: TIER_1A | F146: low | G146: Wave 3 | H146: spider | I146: One bespoke spider or fetcher per source | J146: Z_bespoke | K146: Custom | L146: retailer_sku | M146: supermarket | N146: AMD | O146: 150 | P146: /en/products/_<id>/ | Q146: GET /en/products/_723530/ -> 200, 399KB. PDP h1 'Pasta Zara No. 50 500g', span.priceValue = '710 dr'. Category tree via /en/products/_<id>/ product links visible on homepage. | R146: TRUE | S146: Weight-based items sliced to order per CSV note; PDP price rendered server-side.
A147: eca | B147: bulgaria | C147: T Market Online | D147: https://tmarketonline.bg/ | E147: TIER_1A | F147: low | G147: Wave 3 | H147: spider | I147: One bespoke spider or fetcher per source | J147: Z_bespoke | K147: Custom | L147: retailer_sku | M147: supermarket | N147: BGN/EUR | O147: 150 | P147: SSR product pages | Q147: GET /product/avokado-izrael -> h1 'Avokado, br.' (avocado), price '1,39 lv' / '0,71 EUR'. Real /product/<slug> and /category/<slug> links throughout homepage. | R147: TRUE | S147: Maxima-group chain; CSV flags unusually good fresh + LOCAL Bulgarian lines (rose tomatoes, Madzharov cheese, banitsa sheets).
A148: eca | B148: finland | C148: Prisma | D148: https://www.prisma.fi/ | E148: TIER_1A | F148: low | G148: Wave 3 | H148: spider | I148: One bespoke spider or fetcher per source | J148: Z_bespoke | K148: Custom (Next.js) | L148: retailer_sku | M148: supermarket | N148: EUR | O148: 150 | P148: SSR + __NEXT_DATA__ | Q148: GET / -> 200, 1.04MB, __NEXT_DATA__ present, real EUR prices rendered server-side (e.g. '5 439,15 €' owner-price banner item). Same S-Group family as s-kaupat.fi. Grocery category page not separately fetched this round. | R148: TRUE | S148: Homepage sample was a big-ticket appliance, not F&B -- grocery category page needs a follow-up fetch to confirm F&B depth directly, but platform/SSR confirmed working.
...

Sheet Remaining_125
A1: region | B1: slug | C1: source | D1: url | E1: tier | F1: effort | G1: build_wave | H1: scaffolding | I1: build_approach | J1: bucket | K1: platform | L1: analytical_role | M1: channel | N1: currency | O1: fnb_leaves_est | P1: endpoint | Q1: evidence | R1: in_csv | S1: notes | T1: gotcha
A2: eca | B2: tajikistan | C2: Dado.tj | D2: https://dado.tj/ | E2: TIER_1B | F2: medium | G2: Wave 4 | H2: spider | I2: Bespoke spider/fetcher - endpoint already known; extra work is pagination, auth or parsing | J2: D_woocommerce | K2: WooCommerce | L2: retailer_sku | M2: supermarket | N2: TJS | O2: 90 | P2: /wp-json/wc/store/v1/products (price field currently unreliable) | Q2: WordPress+WooCommerce confirmed. GET /wp-json/wc/store/v1/products?per_page=20 -> HTTP 200, structured JSON, TJS currency, but price=0 for every one of 25 sampled products across 2 pages. Frontend PDP for a different product (h1 'Yabloko Sultanat' -- apple) shows a real non-zero price '4.89c.' rendered in the page. Product-category nav includes fresh produce (arbuz/watermelon, chesnok/garlic) alongside household chemicals. | R2: TRUE | S2: DATA QUALITY CAVEAT: the Store API endpoint works structurally but returns price=0 site-wide while the HTML frontend shows real prices -- looks like a price-sync bug on the store's own catalogue, not a scraping problem. Would need to scrape rendered PDP HTML instead of trusting the API price field until this is resolved.
A3: eca | B3: germany | C3: Liefershop.de | D3: https://www.liefershop.de/ | E3: TIER_1B | F3: medium | G3: Wave 4 | H3: spider | I3: Bespoke spider/fetcher - endpoint already known; extra work is pagination, auth or parsing | J3: D_woocommerce | K3: WooCommerce | L3: retailer_sku | M3: supermarket | N3: EUR | O3: 60 | P3: /wp-json/wc/store/v1/products?per_page=N&page=N | Q3: WooCommerce Store API /wp-json/wc/store/v1/products confirmed working (HTTP 200). Page 1 returned mostly Juice Plus+ MLM products, but page 5 (offset) returned genuine F&B SKUs: 'Lamotte & Cie Champagne Brut', 'Tavernello Vino Rosato d'Italia', 'Kosakenkaffee', 'Carpe Diem Kombucha Classic', 'Saupiquet Thunfisch-Salat Mexicana', 'Küstengold Spargelabschnitte', 'Cinema Popcorn süss', 'Heisse Tasse Tomaten-Creme-Suppe', 'Nestlé Cerealien Mini Packs', 'Corny Müsli-Riegel' | R3: TRUE | S3: CSV gotcha confirmed and worse than described: catalog is heavily contaminated with Juice Plus+ MLM shake/supplement products interleaved with real wine/beverage/pantry SKUs - needs an MLM-brand filter before use.
A4: lac | B4: chile | C4: Jumbo Chile | D4: https://www.jumbo.cl/ | E4: TIER_1B | F4: medium | G4: Wave 4 | H4: spider | I4: Bespoke spider/fetcher - endpoint already known; extra work is pagination, auth or parsing | J4: E_vtex | K4: VTEX | L4: retailer_sku | M4: supermarket | N4: CLP | O4: 155 | P4: /api/catalog_system/pub/products/search (via jumbocl.myvtex.com origin, not the WAF'd custom domain) | Q4: Custom domain jumbo.cl/api/... 404s (Next.js frontend not proxying legacy API). VTEX origin GET https://jumbocl.myvtex.com/api/catalog_system/pub/products/search?_from=0&_to=5 -> HTTP 206, 110476 bytes. Sample: 'Platano Extra Granel (1 a 2 un. Aprox)' CLP 1590.0, link resolves to jumbocl.myvtex.com/platano-granel/p | R4: FALSE | S4: Cencosud CL flagship hypermarket. Spider must target the myvtex.com origin, not jumbo.cl, mirroring the Shopify *.myshopify.com origin trick in platform_fingerprints.md.
A5: lac | B5: paraguay | C5: Arete Supermercados | D5: https://arete.com.py/ | E5: TIER_1A | F5: medium | G5: Wave 4 | H5: spider | I5: Bespoke spider/fetcher - endpoint already known; extra work is pagination, auth or parsing | J5: E_vtex | K5: Custom (same URL shape/vendor as Casa Rica; a 'GET /api/catalog_system/...' probe on this domain returned the platform's own JSON error 'La funcion solicitada no existe', confirming it is NOT VTEX) | L5: retailer_sku | M5: supermarket | N5: PYG | O5: 150 | P5: /catalogo/<category-slug>-c<id> | Q5: GET https://arete.com.py/catalogo/arroz-c347 -> HTTP 200, 200343 bytes SSR HTML. Sample: 'ARROZ ENOC INTEGRAL 1 KG' Gs. 14.000 (other rows on same page: Gs. 2.850 / 5.500 / 5.200 / 9.950). Homepage has 162 distinct /catalogo/*-c<id> categories incl. aceites, arroz, frutas, frutas-y-verduras, leche-condensada. | R5: FALSE | S5: Second full-line PY chain on the same platform family as Casa Rica -- high category overlap expected.
A6: lac | B6: chile | C6: Santa Isabel | D6: https://www.santaisabel.cl/ | E6: TIER_1B | F6: medium | G6: Wave 4 | H6: spider | I6: Bespoke spider/fetcher - endpoint already known; extra work is pagination, auth or parsing | J6: E_vtex | K6: VTEX | L6: retailer_sku | M6: supermarket | N6: CLP | O6: 140 | P6: /api/catalog_system/pub/products/search (via santaisabel.myvtex.com origin) | Q6: Custom domain santaisabel.cl/api/... 404s. VTEX origin GET https://santaisabel.myvtex.com/api/catalog_system/pub/products/search?_from=0&_to=5 -> HTTP 206, 97397 bytes. Sample: 'Trutro Entero de Pollo kg' CLP 3990.0 | R6: FALSE | S6: Cencosud CL supermarket banner, fresh meat confirmed. Same myvtex-origin caveat as Jumbo CL.
A7: lac | B7: ecuador | C7: Tia | D7: https://www.tia.com.ec/supermercado | E7: TIER_1A | F7: medium | G7: Wave 4 | H7: spider | I7: Bespoke spider/fetcher - endpoint already known; extra work is pagination, auth or parsing | J7: H_magento | K7: Magento 2 (SSR HTML) | L7: retailer_sku | M7: supermarket | N7: USD | O7: 165 | P7: /supermercado/<category>/<subcategory> (Magento 2 SSR category pages; /catalogsearch/result redirect confirms Magento) | Q7: GET https://www.tia.com.ec/supermercado/frutas-y-verduras/frutas -> HTTP 200, 319188 bytes SSR HTML. Product name + price directly in listing markup: 'ARANDANO BANDEJA 125 G' USD 1.59 (class=product-item-name / product-item-link). Full /supermercado nav tree includes aguas-y-bebidas, comestibles/{aceites-y-vinagres, arroz-y-fideos, cafe-y-chocolate-en-polvo, cereales-y-granolas, dulces-postres-y-untables, enlatados-y-conservas, granos-y-semillas, harinas-y-avenas, te-y-aromaticas}, desechables, frutas-y-verduras, lacteos/{crema-de-leche, huevos, leche-en-polvo, leches-blancas, leches-saborizadas, leches-vegetales, quesos, yogurt}, pastas, snacks-y-golosinas/{cakes-y-bocaditos, chocolates, galletas, papas-fritas, snacks-de-maiz}. | R7: FALSE | S7: Ecuador's largest variety/discount retailer, full grocery vertical confirmed via nav tree. Magento GraphQL (/graphql) 403s -- scrape via SSR category pagination instead.
A8: ssa | B8: senegal | C8: Kaynoo | D8: https://www.kaynoo.sn/epicerie.html | E8: TIER_1B | F8: medium | G8: Wave 4 | H8: spider | I8: Bespoke spider/fetcher - endpoint already known; extra work is pagination, auth or parsing | J8: H_magento | K8: Magento | L8: retailer_sku | M8: supermarket | N8: XOF | O8: 45 | P8: Magento GraphQL or /rest/V1/products | Q8: GET /epicerie.html -> 200, 361KB, Magento fingerprint confirmed (price-box price-final_price divs, data-price-amount='2500'/'4500'/'4000' on real product ids). Catalogue mixes food with cosmetics per prior research -- filter by category. | R8: TRUE | S8: Strong on local items (cafe Touba in 3 pack sizes, moringa/nebeday, baobab-adjacent) but heavy overlap with Sakanal/Yombouna's epicerie coverage -- most of its value is depth on a handful of leaves, not breadth.
A9: eca | B9: croatia | C9: Konzum | D9: https://www.konzum.hr/kreni-u-kupnju | E9: TIER_1A | F9: medium | G9: Wave 4 | H9: spider | I9: Bespoke spider/fetcher - endpoint already known; extra work is pagination, auth or parsing | J9: Z_bespoke | K9: Next.js | L9: retailer_sku | M9: supermarket | N9: EUR | O9: 170 | P9: SSR category HTML | Q9: GET -> 200, 291KB SSR (Next.js). Direct prices in HTML: 1,49€ / 2,99€ / 3,99€ / 180,00€. | R9: TRUE | S9: 12,000+ products; per shard, 5 price fields per SKU (current/unit-per-kg/30-day-low/reference-date/promo-end) -- capture all 5, not just current.
A10: lac | B10: paraguay | C10: Casa Rica | D10: https://www.casarica.com.py/ | E10: TIER_1A | F10: medium | G10: Wave 4 | H10: spider | I10: Bespoke spider/fetcher - endpoint already known; extra work is pagination, auth or parsing | J10: Z_bespoke | K10: Custom (shared by several PY grocery sites, same '/catalogo/*-c<id>' URL shape and identical API error string) | L10: retailer_sku | M10: supermarket | N10: PYG | O10: 165 | P10: /catalogo/<category-slug>-c<id> (custom PY grocery-platform vendor, SSR HTML, paginated) | Q10: GET https://www.casarica.com.py/catalogo/aceite-de-girasol-c2 -> HTTP 200, 286701 bytes SSR HTML. Products+prices directly in markup: 'ACEITE CANUELAS GIRASOL 1.5LT' Gs. 29.000, 'ACEITE COCINERO GIRASOL PET 900ML' Gs. 21.000. Homepage lists 261 distinct /catalogo/<slug>-c<id> category links spanning vacuno (beef), verduleria-fruteria, verduras, semiblandos/semiduros (cheese), yogurt-entero/dietetico, salames, rotiseria, sal, te, yerba, vinos by country, sidras. | R10: FALSE | S10: Full-line Asuncion-area supermarket chain incl. fresh meat/produce/deli.
A11: eca | B11: netherlands | C11: Jumbo | D11: https://www.jumbo.com/ | E11: TIER_1A | F11: medium | G11: Wave 4 | H11: spider | I11: Bespoke spider/fetcher - endpoint already known; extra work is pagination, auth or parsing | J11: Z_bespoke | K11: Vue | L11: retailer_sku | M11: supermarket | N11: EUR | O11: 160 | P11: SSR category HTML (/producten/) | Q11: GET /producten/ -> 200, 1.32MB SSR (Vue). Product cards found (data-testid='product-card-0', data-product-id='765935ZK') with 'Prijs: € 3,25' in the price DOM. | R11: TRUE | S11: Overturns shard's D-tier 'SUSPECT' prediction -- category page renders server-side with real product cards, no WAF. ~20-22k articles per shard; runs a lowest-price-guarantee mechanically tied to competitors.
A12: eca | B12: spain | C12: Precios del Super | D12: https://preciosdelsuper.es/ | E12: TIER_1A | F12: medium | G12: Wave 4 | H12: spider | I12: Bespoke spider/fetcher - endpoint already known; extra work is pagination, auth or parsing | J12: Z_bespoke | K12: Custom | L12: retailer_sku | M12: aggregator | N12: EUR | O12: 160 | P12: SSR listing HTML | Q12: GET -> 200, 124KB SSR. Direct prices '2,99€' / '16,95€' in HTML. | R12: TRUE | S12: 120,000+ products across 8 supermarkets per shard, with per-product price history and a daily changes feed.
A13: eca | B13: georgia | C13: Wolt Market Georgia | D13: https://wolt.com/en/geo/tbilisi/category/grocery | E13: TIER_1B | F13: medium | G13: Wave 4 | H13: spider | I13: Bespoke spider/fetcher - endpoint already known; extra work is pagination, auth or parsing | J13: Z_bespoke | K13: Custom (Wolt public API) | L13: retailer_sku | M13: aggregator | N13: GEL | O13: 150 | P13: restaurant-api.wolt.com/v1/pages/restaurants | Q13: GET https://restaurant-api.wolt.com/v1/pages/restaurants?lat=41.7151&lon=44.8271 -> HTTP 200, 2.77MB JSON, 1315 venues in the 'restaurants-delivering-venues' section for Tbilisi (includes named grocery chains: SPAR, IOLI, Rkoni, Europroduct, Smart, etc. per CSV). Public API, no auth required. | R13: TRUE | S13: Directory endpoint confirmed; per-venue menu endpoint (restaurant-api.wolt.com/v3/venues/slug/<slug>/menu/data) not individually tested this round but is a documented Wolt pattern. Aggregator margin caveat applies vs shelf price.
... A17: ssa | B17: mozambique | C17: RECHEIO Cash & Carry | D17: https://recheio.co.mz/ | E17: TIER_1A | F17: medium | G17: Wave 4 | H17: spider | I17: Bespoke spider/fetcher - endpoint already known; extra work is pagination, auth or parsing | J17: Z_bespoke | K17: Custom (ASP.NET-style) | L17: retailer_sku | M17: supermarket | N17: MZN | O17: 120 | P17: unresolved exact product endpoint -- category page confirmed live | Q17: GET / -> 200, 141KB. Attempted category page GET /loja/mercearia -> 200, 40KB, real title 'Mercearia ao Melhor Preco em Mocambique' confirming the category exists live, but no price-class markup surfaced in that page's raw HTML this pass (likely paginated/AJAX-loaded product grid). | R17: TRUE | S17: 1,456 products in mercearia alone + full aisle taxonomy (lacticinios, carne e peixe, bebidas, vegetais, loja asiatica) per prior research -- best Mozambique source, but I could not independently pull a live price this pass so the estimate is held below the presumed max.
A18: eap | B18: japan | C18: opengov.jp Retail Price Survey (re-publication of MIC Statistics Bureau retail price survey) | D18: https://opengov.jp/en/prices/retail-prices/ | E18: TIER_1A | F18: medium | G18: Wave 4 | H18: fetcher | I18: Bespoke spider/fetcher - endpoint already known; extra work is pagination, auth or parsing | J18: Z_bespoke | K18: Custom | L18: official_avg | N18: JPY | O18: 115 | P18: /en/prices/retail-prices/<code>/ (per-item static HTML page; codes prefixed 01xx = food, 02xx = alcohol) | Q18: GET /en/prices/retail-prices/ -> 200, 366KB HTML, 541 item-code links with English names, e.g. '01001 | Rice A', '01101 | Tuna', '01414 | Daikon radish', '01131 | Short-neck clam'. GET /en/prices/retail-prices/01001/ -> 200, title 'Rice A Retail Prices', year table: 2026 Jan national-average price JPY 5,317 (+27.0% YoY). Plain curl with a browser UA, no JS, no auth. | R18: FALSE | S18: 541 total item codes span the whole CPI basket by prefix: 01=207 items (food), 02=32 (alcohol), 03-09=302 (rent/clothing/health/education/personal care, out of scope). The 01+02 subset reaches deep, specific division-01 leaves current Japan sources miss entirely -- named fish species (tuna, horse mackerel, sardine, salmon, mackerel, sea bream, yellowtail, squid, octopus, shrimp, clam, oyster, scallop -> COICOP 01.1.3.x), named vegetables (cabbage, lettuce, daikon, broccoli, spinach, onion, ginger -> 01.1.7.x), noodles/rice/bread/flour, dairy, and Sake/Shochu/Chuhai for div-02. Japan's existing onboarded set (rakuten, yahoo_shopping, docomo, athome_jp, homes_jp, hotpepper_jp) is mostly non-grocery (real estate, mobile plans, restaurant bookings) -- this is likely Japan's primary deep-F&B channel, not a supplement. CAVEAT not fully resolved this session: the item page shown is a Year+Jan-value summary table; unclear whether opengov.jp exposes the full monthly series the underlying survey actually produces, or only this annual snapshot -- verify cadence before onboarding. 541 pages to walk (one HTTP call per item) makes this medium, not low, effort.
A19: eca | B19: azerbaijan | C19: Wolt Baku grocery (aggregator) | D19: https://wolt.com/en/aze/baku/category/grocery | E19: TIER_1B | F19: medium | G19: Wave 4 | H19: spider | I19: Bespoke spider/fetcher - endpoint already known; extra work is pagination, auth or parsing | J19: Z_bespoke | K19: Custom | L19: retailer_sku | M19: aggregator | N19: AZN | O19: 100 | P19: page-embedded JSON | Q19: GET -> 200, 2MB. Embedded JSON: store list w/ prices e.g. 'price':935 (9.35 AZN); store names include 'SPAR Ehmed Recebli','Bravo Supermarket Winter Park','Araz Statistics 2 Supermarket','Tamstore Express Fountain sq.','Oba Market Ahmadli'. | R19: TRUE | S19: Marketplace directory of ~7 Baku chains, several labelled 'same prices as in store'. Treat as directory first: consolation-prize catalog scrape only if per-store storefronts fail.
A20: lac | B20: st_vincent_and_the_grenadines | C20: C.K. Greaves & Company | D20: https://www.ckgreaves.com/ | E20: TIER_1A | F20: medium | G20: Wave 4 | H20: spider | I20: Bespoke spider/fetcher - endpoint already known; extra work is pagination, auth or parsing | J20: Z_bespoke | K20: WordPress + custom shop module | L20: retailer_sku | M20: supermarket | N20: XCD | O20: 100 | P20: /shop/browse/product/{id}_{slug}/ (SSR PDP) | Q20: GET /shop/browse/product/19751_b-bird-apple-juice-340ml/ -> HTTP 200, 102KB HTML with real embedded price markup ('<div class="price-now..."><span class="sym">$</span><strong class="dol">4</strong><em class="dec">35</em></div>' = $4.35) for product 'B Bird Apple Juice 340ml'. Product catalog browsable via /departments/ and /shop/browse/product/ paths (WordPress-hosted custom storefront, not WooCommerce core — /wp-json/wc/store/v1/products returned HTTP 404). | R20: FALSE | S20: Currency shown only as generic '$' symbol; XCD assumed from SVG's official currency per country-currency conventions (not confirmed by an explicit currency code in the page). Catalog skews packaged goods (juice, tea, cleaning, pet products) in the pages sampled — fresh produce/meat depth unconfirmed.
A21: sar | B21: nepal | C21: MeroKirana | D21: https://merokirana.com/ | E21: TIER_1B | F21: medium | G21: Wave 4 | H21: spider | I21: Bespoke spider/fetcher - endpoint already known; extra work is pagination, auth or parsing | J21: Z_bespoke | K21: Custom (Semantro) | L21: retailer_sku | M21: supermarket | N21: NPR | O21: 95 | P21: POST /semantro-web-interface/query | Q21: React SPA over a proprietary 'Semantro' backend at POST https://merokirana.com/semantro-web-interface/query (multipart form field 'data' = JSON action descriptor, plain curl, no auth/cookies). actionName=listBaseCategories -> 10 categories incl. Veg & Fruits, Eggs & Meat, Bakery & Dairy. actionName=listLatestProducts (pageLimit start/end) -> product id list. actionName=getProductData per product -> price+currency. Verified end-to-end: 'Kejjan's Snail Mucin & Rice Water Face Toner, 150ml' -> priceCurrency 'NRs.', price 555.0. | R21: TRUE | S21: Only category-scoped listing action name unconfirmed in the time budget (listLatestProducts has no categoryId param seen); listBaseCategories + getProductData are proven and category id is already known ('Veg & Fruits' id=35ae95a75bda48a3-ac60b32fab01d5db) so a category-listing action almost certainly exists next to listLatestProducts -- probe further before scaffolding. DDC (state dairy) lines per shard notes.
